{"ts_mono_ns":10862939090045,"ts_wall_ns":1788920377503571187,"fonte":"poly_ws","payload":{"market":"0x73fd6c72d0bf8220003943b6e2b41292b8cd4d97c27314db06735789b59e9d09","price_changes":[{"asset_id":"113917660431940170818498786968146153783642292134565871228813850528518440127962","price":"0.37","size":"0","side":"BUY","hash":"91a1fda0775af8bc5404b442da6835122dd76cb5","best_bid":"0.36","best_ask":"0.38"},{"asset_id":"84363210919223921947447886444210431825911105421883946794723950657543270560538","price":"0.63","size":"0","side":"SELL","hash":"35727ff04ea22fedafa4de1c812884b811579e26","best_bid":"0.62","best_ask":"0.64"}],"timestamp":"1788920376686","event_type":"price_change"}}
{"ts_mono_ns":10862939173288,"ts_wall_ns":1788920377503654430,"fonte":"poly_ws","payload":{"market":"0xf250e9cda122a88bffb973a0c10d67302f06c4d6d2a7a998bbd514c9b783cb9c","price_changes":[{"asset_id":"30628628256922129361568138552829834868125997804575067220632439143002067301195","price":"0.29","size":"324","side":"BUY","hash":"bd7af937e7a0f204037bc131c88b36864d71c9c1","best_bid":"0.33","best_ask":"0.34"},{"asset_id":"25904534922361021063199958329408275661746575318235828101794830786745156915675","price":"0.71","size":"324","side":"SELL","hash":"407cd7a3b5c81175c91a74ea9945348821bbaa1d","best_bid":"0.66","best_ask":"0.67"}],"timestamp":"1788920376687","event_type":"price_change"}}
{"ts_mono_ns":10862939203981,"ts_wall_ns":1788920377503685123,"fonte":"poly_ws","payload":{"market":"0xf250e9cda122a88bffb973a0c10d67302f06c4d6d2a7a998bbd514c9b783cb9c","price_changes":[{"asset_id":"30628628256922129361568138552829834868125997804575067220632439143002067301195","price":"0.29","size":"199","side":"BUY","hash":"269f648d7ca44608a3a68a3f34dc45abcc0535b1","best_bid":"0.33","best_ask":"0.34"},{"asset_id":"25904534922361021063199958329408275661746575318235828101794830786745156915675","price":"0.71","size":"199","side":"SELL","hash":"b4cfcfd08e5df6b718f2c457859f9031dad21e9c","best_bid":"0.66","best_ask":"0.67"}],"timestamp":"1788920376687","event_type":"price_change"}}
{"ts_mono_ns":10862939227402,"ts_wall_ns":1788920377503708544,"fonte":"poly_ws","payload":{"market":"0x583e8a11679a33294b1e20a89374e4742961f151f1f05c9a0c1eb34883a7538f","price_changes":[{"asset_id":"46179897111767575621067600626085063615255126374895750367620822995125397577982","price":"0.01","size":"3635.08","side":"BUY","hash":"a110138e158ce8fe150d6ad761666070c6f1a97e","best_bid":"0.999","best_ask":"1"},{"asset_id":"72709494218706655003179124592746636178529103451837436693660676934739929402705","price":"0.99","size":"3635.08","side":"SELL","hash":"fc28a17cb16f4cfce334bde0bbda7957865470db","best_bid":"0","best_ask":"0.001"}],"timestamp":"1788920376691","event_type":"price_change"}}
{"ts_mono_ns":10862939305191,"ts_wall_ns":1788920377503786418,"fonte":"poly_ws","payload":{"market":"0x583e8a11679a33294b1e20a89374e4742961f151f1f05c9a0c1eb34883a7538f","price_changes":[{"asset_id":"46179897111767575621067600626085063615255126374895750367620822995125397577982","price":"0.01","size":"3629.08","side":"BUY","hash":"3c995c95881530c6192c9e6e3a952a6f24b45c04","best_bid":"0.999","best_ask":"1"},{"asset_id":"72709494218706655003179124592746636178529103451837436693660676934739929402705","price":"0.99","size":"3629.08","side":"SELL","hash":"4abe07da05950204a746e29b0e377a406c50ed40","best_bid":"0","best_ask":"0.001"}],"timestamp":"1788920376691","event_type":"price_change"}}
{"ts_mono_ns":10862939335462,"ts_wall_ns":1788920377503816604,"fonte":"poly_ws","payload":{"market":"0x583e8a11679a33294b1e20a89374e4742961f151f1f05c9a0c1eb34883a7538f","price_changes":[{"asset_id":"46179897111767575621067600626085063615255126374895750367620822995125397577982","price":"0.01","size":"3624.08","side":"BUY","hash":"7a71ee50f5327f74da45e02ef72672a2590f1b7a","best_bid":"0.999","best_ask":"1"},{"asset_id":"72709494218706655003179124592746636178529103451837436693660676934739929402705","price":"0.99","size":"3624.08","side":"SELL","hash":"9a8c54ab784f21d55c753576efdc1acbfee57052","best_bid":"0","best_ask":"0.001"}],"timestamp":"1788920376705","event_type":"price_change"}}
{"ts_mono_ns":10862939385813,"ts_wall_ns":1788920377503866956,"fonte":"poly_ws","payload":{"market":"0x73fd6c72d0bf8220003943b6e2b41292b8cd4d97c27314db06735789b59e9d09","price_changes":[{"asset_id":"113917660431940170818498786968146153783642292134565871228813850528518440127962","price":"0.37","size":"24","side":"BUY","hash":"6be1a666054c53a95f4e75972e6a6b9f2810c5f9","best_bid":"0.37","best_ask":"0.38"},{"asset_id":"84363210919223921947447886444210431825911105421883946794723950657543270560538","price":"0.63","size":"24","side":"SELL","hash":"2876601a464f3900134f8003aa52c5e234fa0883","best_bid":"0.62","best_ask":"0.63"}],"timestamp":"1788920376708","event_type":"price_change"}}
{"ts_mono_ns":10862939427414,"ts_wall_ns":1788920377503908556,"fonte":"poly_ws","payload":{"market":"0xf250e9cda122a88bffb973a0c10d67302f06c4d6d2a7a998bbd514c9b783cb9c","price_changes":[{"asset_id":"30628628256922129361568138552829834868125997804575067220632439143002067301195","price":"0.01","size":"1918.75","side":"BUY","hash":"12ae9713b7cb96bd52c4001afa3cf21927c4122e","best_bid":"0.33","best_ask":"0.34"},{"asset_id":"25904534922361021063199958329408275661746575318235828101794830786745156915675","price":"0.99","size":"1918.75","side":"SELL","hash":"2a9b8473f5bf8e3842fd5fff5162a6019571130d","best_bid":"0.66","best_ask":"0.67"}],"timestamp":"1788920376717","event_type":"price_change"}}
{"ts_mono_ns":10862939448637,"ts_wall_ns":1788920377503929779,"fonte":"poly_ws","payload":{"market":"0xf250e9cda122a88bffb973a0c10d67302f06c4d6d2a7a998bbd514c9b783cb9c","price_changes":[{"asset_id":"25904534922361021063199958329408275661746575318235828101794830786745156915675","price":"0.01","size":"1794.75","side":"BUY","hash":"66ba487eed3f0811eb58bc65e7d033370ebb1c6c","best_bid":"0.66","best_ask":"0.67"},{"asset_id":"30628628256922129361568138552829834868125997804575067220632439143002067301195","price":"0.99","size":"1794.75","side":"SELL","hash":"d38cf20f1a822644461427ad799bbfe54391899d","best_bid":"0.33","best_ask":"0.34"}],"timestamp":"1788920376718","event_type":"price_change"}}
{"ts_mono_ns":10862939471001,"ts_wall_ns":1788920377503952186,"fonte":"poly_ws","payload":{"market":"0xf250e9cda122a88bffb973a0c10d67302f06c4d6d2a7a998bbd514c9b783cb9c","price_changes":[{"asset_id":"30628628256922129361568138552829834868125997804575067220632439143002067301195","price":"0.01","size":"1923.75","side":"BUY","hash":"563aca9c544a9b56997d248c36863c3d02fb9232","best_bid":"0.33","best_ask":"0.34"},{"asset_id":"25904534922361021063199958329408275661746575318235828101794830786745156915675","price":"0.99","size":"1923.75","side":"SELL","hash":"940a79fd856b7b4a4a8ba799e718c365bb208bea","best_bid":"0.66","best_ask":"0.67"}],"timestamp":"1788920376719","event_type":"price_change"}}
{"ts_mono_ns":10862939494803,"ts_wall_ns":1788920377503975945,"fonte":"poly_ws","payload":{"market":"0xf250e9cda122a88bffb973a0c10d67302f06c4d6d2a7a998bbd514c9b783cb9c","price_changes":[{"asset_id":"25904534922361021063199958329408275661746575318235828101794830786745156915675","price":"0.01","size":"1799.75","side":"BUY","hash":"ccfc7171423f3be3ce6e1975ecf8dbf9baed7d7c","best_bid":"0.66","best_ask":"0.67"},{"asset_id":"30628628256922129361568138552829834868125997804575067220632439143002067301195","price":"0.99","size":"1799.75","side":"SELL","hash":"9e76dd0ff9b49d1d3b691620fe1a892cd42244cf","best_bid":"0.33","best_ask":"0.34"}],"timestamp":"1788920376720","event_type":"price_change"}}
{"ts_mono_ns":10862939514250,"ts_wall_ns":1788920377503995393,"fonte":"poly_ws","payload":{"market":"0xf250e9cda122a88bffb973a0c10d67302f06c4d6d2a7a998bbd514c9b783cb9c","price_changes":[{"asset_id":"25904534922361021063199958329408275661746575318235828101794830786745156915675","price":"0.55","size":"256","side":"BUY","hash":"8a36ec8a0208885e11055a9f304936ffbb9af693","best_bid":"0.66","best_ask":"0.67"},{"asset_id":"30628628256922129361568138552829834868125997804575067220632439143002067301195","price":"0.45","size":"256","side":"SELL","hash":"09d80dbe811904a6d1e7f83f2a6d838dbc84211c","best_bid":"0.33","best_ask":"0.34"}],"timestamp":"1788920376721","event_type":"price_change"}}
{"ts_mono_ns":10862939533824,"ts_wall_ns":1788920377504014967,"fonte":"poly_ws","payload":{"market":"0xf250e9cda122a88bffb973a0c10d67302f06c4d6d2a7a998bbd514c9b783cb9c","price_changes":[{"asset_id":"25904534922361021063199958329408275661746575318235828101794830786745156915675","price":"0.82","size":"206","side":"SELL","hash":"1061c2ad073a844afa7f1d22601c6c6666f0dd61","best_bid":"0.66","best_ask":"0.67"},{"asset_id":"30628628256922129361568138552829834868125997804575067220632439143002067301195","price":"0.18","size":"206","side":"BUY","hash":"3d0dfeb0c44d45d9b7b3887d395093efe1559f24","best_bid":"0.33","best_ask":"0.34"}],"timestamp":"1788920376721","event_type":"price_change"}}
{"ts_mono_ns":10862939555470,"ts_wall_ns":1788920377504036697,"fonte":"poly_ws","payload":{"market":"0xf250e9cda122a88bffb973a0c10d67302f06c4d6d2a7a998bbd514c9b783cb9c","price_changes":[{"asset_id":"25904534922361021063199958329408275661746575318235828101794830786745156915675","price":"0.01","size":"1804.75","side":"BUY","hash":"78c4f16faf72c31365cf98f357423c7f05d2d0fb","best_bid":"0.66","best_ask":"0.67"},{"asset_id":"30628628256922129361568138552829834868125997804575067220632439143002067301195","price":"0.99","size":"1804.75","side":"SELL","hash":"144764371f2d2a656ccd2bc1232b240440de9b3b","best_bid":"0.33","best_ask":"0.34"}],"timestamp":"1788920376722","event_type":"price_change"}}
{"ts_mono_ns":10862940441550,"ts_wall_ns":1788920377504922693,"fonte":"poly_ws","payload":{"market":"0xf250e9cda122a88bffb973a0c10d67302f06c4d6d2a7a998bbd514c9b783cb9c","price_changes":[{"asset_id":"30628628256922129361568138552829834868125997804575067220632439143002067301195","price":"0.01","size":"1928.75","side":"BUY","hash":"0c52bb512d9db26d13f541c94e50643c152eadb5","best_bid":"0.33","best_ask":"0.34"},{"asset_id":"25904534922361021063199958329408275661746575318235828101794830786745156915675","price":"0.99","size":"1928.75","side":"SELL","hash":"9099f33bb99e229eb18568898dd376dcd6c90678","best_bid":"0.66","best_ask":"0.67"}],"timestamp":"1788920376723","event_type":"price_change"}}
{"ts_mono_ns":10862940476851,"ts_wall_ns":1788920377504957994,"fonte":"poly_ws","payload":{"market":"0x73fd6c72d0bf8220003943b6e2b41292b8cd4d97c27314db06735789b59e9d09","price_changes":[{"asset_id":"84363210919223921947447886444210431825911105421883946794723950657543270560538","price":"0.54","size":"586","side":"BUY","hash":"886054a8c9b1cba213290edcb59c74f120d414e9","best_bid":"0.62","best_ask":"0.63"},{"asset_id":"113917660431940170818498786968146153783642292134565871228813850528518440127962","price":"0.46","size":"586","side":"SELL","hash":"9165a4c66551747f99100a77131bd76ead456d5d","best_bid":"0.37","best_ask":"0.38"}],"timestamp":"1788920376730","event_type":"price_change"}}
{"ts_mono_ns":10862940503528,"ts_wall_ns":1788920377504984671,"fonte":"poly_ws","payload":{"market":"0x73fd6c72d0bf8220003943b6e2b41292b8cd4d97c27314db06735789b59e9d09","price_changes":[{"asset_id":"84363210919223921947447886444210431825911105421883946794723950657543270560538","price":"0.75","size":"169","side":"SELL","hash":"c24504f72d185d9394bbd9882059d149520777c1","best_bid":"0.62","best_ask":"0.63"},{"asset_id":"113917660431940170818498786968146153783642292134565871228813850528518440127962","price":"0.25","size":"169","side":"BUY","hash":"7deba0bc3ce8266e45eedf53e956238e2954a537","best_bid":"0.37","best_ask":"0.38"}],"timestamp":"1788920376731","event_type":"price_change"}}
{"ts_mono_ns":10862940523821,"ts_wall_ns":1788920377505005006,"fonte":"poly_ws","payload":{"market":"0xf250e9cda122a88bffb973a0c10d67302f06c4d6d2a7a998bbd514c9b783cb9c","price_changes":[{"asset_id":"30628628256922129361568138552829834868125997804575067220632439143002067301195","price":"0.28","size":"2008","side":"BUY","hash":"bb0891b62356a0188ae496c2ecdde33e467169be","best_bid":"0.33","best_ask":"0.34"},{"asset_id":"25904534922361021063199958329408275661746575318235828101794830786745156915675","price":"0.72","size":"2008","side":"SELL","hash":"33e18f115aa2fdb33763e1cd24e75529822ddc5f","best_bid":"0.66","best_ask":"0.67"}],"timestamp":"1788920376737","event_type":"price_change"}}
{"ts_mono_ns":10862940543860,"ts_wall_ns":1788920377505025003,"fonte":"poly_ws","payload":{"market":"0xf250e9cda122a88bffb973a0c10d67302f06c4d6d2a7a998bbd514c9b783cb9c","price_changes":[{"asset_id":"30628628256922129361568138552829834868125997804575067220632439143002067301195","price":"0.27","size":"1532.11","side":"BUY","hash":"bc16bec8ba3a9f2eca6bd26ca17fc0f41c32d05f","best_bid":"0.33","best_ask":"0.34"},{"asset_id":"25904534922361021063199958329408275661746575318235828101794830786745156915675","price":"0.73","size":"1532.11","side":"SELL","hash":"a7cbff460564bda7697e91a3369386d54264864f","best_bid":"0.66","best_ask":"0.67"}],"timestamp":"1788920376738","event_type":"price_change"}}
{"ts_mono_ns":10862940562758,"ts_wall_ns":1788920377505043900,"fonte":"poly_ws","payload":{"market":"0xf250e9cda122a88bffb973a0c10d67302f06c4d6d2a7a998bbd514c9b783cb9c","price_changes":[{"asset_id":"30628628256922129361568138552829834868125997804575067220632439143002067301195","price":"0.29","size":"666","side":"BUY","hash":"daffdc51bdad7e65696ee3d9805941444ed98bd0","best_bid":"0.33","best_ask":"0.34"},{"asset_id":"25904534922361021063199958329408275661746575318235828101794830786745156915675","price":"0.71","size":"666","side":"SELL","hash":"f86dd530526292e97a51b53d14102353da45c30f","best_bid":"0.66","best_ask":"0.67"}],"timestamp":"1788920376739","event_type":"price_change"}}
{"ts_mono_ns":10862940581486,"ts_wall_ns":1788920377505062629,"fonte":"poly_ws","payload":{"market":"0xf250e9cda122a88bffb973a0c10d67302f06c4d6d2a7a998bbd514c9b783cb9c","price_changes":[{"asset_id":"30628628256922129361568138552829834868125997804575067220632439143002067301195","price":"0.33","size":"160","side":"BUY","hash":"e72dff28dc5eac9afbd1ec04ea34e95105f755eb","best_bid":"0.33","best_ask":"0.34"},{"asset_id":"25904534922361021063199958329408275661746575318235828101794830786745156915675","price":"0.67","size":"160","side":"SELL","hash":"e25aa4ec65884faac8405114840b250399ebfc3b","best_bid":"0.66","best_ask":"0.67"}],"timestamp":"1788920376741","event_type":"price_change"}}
{"ts_mono_ns":10862940600342,"ts_wall_ns":1788920377505081485,"fonte":"poly_ws","payload":{"market":"0x73fd6c72d0bf8220003943b6e2b41292b8cd4d97c27314db06735789b59e9d09","price_changes":[{"asset_id":"113917660431940170818498786968146153783642292134565871228813850528518440127962","price":"0.34","size":"259","side":"BUY","hash":"7b44207b9f684351a952be0f522755a49bdec48a","best_bid":"0.37","best_ask":"0.38"},{"asset_id":"84363210919223921947447886444210431825911105421883946794723950657543270560538","price":"0.66","size":"259","side":"SELL","hash":"2ffd7380b96c3bdaa94f1b884838d751a6310781","best_bid":"0.62","best_ask":"0.63"}],"timestamp":"1788920376745","event_type":"price_change"}}
{"ts_mono_ns":10862940617802,"ts_wall_ns":1788920377505098945,"fonte":"poly_ws","payload":{"market":"0xf250e9cda122a88bffb973a0c10d67302f06c4d6d2a7a998bbd514c9b783cb9c","price_changes":[{"asset_id":"25904534922361021063199958329408275661746575318235828101794830786745156915675","price":"0.66","size":"61.44","side":"BUY","hash":"1c395c991a6ffb749b4494fa2fd421c7ef95c4b9","best_bid":"0.66","best_ask":"0.67"},{"asset_id":"30628628256922129361568138552829834868125997804575067220632439143002067301195","price":"0.34","size":"61.44","side":"SELL","hash":"85c6740099e575f192c70db4b0ac6c1cdef924ac","best_bid":"0.33","best_ask":"0.34"}],"timestamp":"1788920376746","event_type":"price_change"}}
{"ts_mono_ns":10862940660544,"ts_wall_ns":1788920377505141729,"fonte":"poly_ws","payload":{"market":"0x73fd6c72d0bf8220003943b6e2b41292b8cd4d97c27314db06735789b59e9d09","price_changes":[{"asset_id":"113917660431940170818498786968146153783642292134565871228813850528518440127962","price":"0.37","size":"0","side":"BUY","hash":"980a8873faa133b42431bb46f3da63d98a3f9d2a","best_bid":"0.36","best_ask":"0.38"},{"asset_id":"84363210919223921947447886444210431825911105421883946794723950657543270560538","price":"0.63","size":"0","side":"SELL","hash":"02a5caafe6c11cfaff7d19643fb77413d4d18c33","best_bid":"0.62","best_ask":"0.64"}],"timestamp":"1788920376748","event_type":"price_change"}}
{"ts_mono_ns":10862940679315,"ts_wall_ns":1788920377505160500,"fonte":"poly_ws","payload":{"market":"0xf250e9cda122a88bffb973a0c10d67302f06c4d6d2a7a998bbd514c9b783cb9c","price_changes":[{"asset_id":"30628628256922129361568138552829834868125997804575067220632439143002067301195","price":"0.01","size":"1923.75","side":"BUY","hash":"5b4006c8d556a42cd929780c8a71893fd7cfc1b9","best_bid":"0.33","best_ask":"0.34"},{"asset_id":"25904534922361021063199958329408275661746575318235828101794830786745156915675","price":"0.99","size":"1923.75","side":"SELL","hash":"ef955b3fceb5aabb023870c93a348bd97f7f6ac8","best_bid":"0.66","best_ask":"0.67"}],"timestamp":"1788920376748","event_type":"price_change"}}
{"ts_mono_ns":10862940698297,"ts_wall_ns":1788920377505179440,"fonte":"poly_ws","payload":{"market":"0x583e8a11679a33294b1e20a89374e4742961f151f1f05c9a0c1eb34883a7538f","price_changes":[{"asset_id":"46179897111767575621067600626085063615255126374895750367620822995125397577982","price":"0.001","size":"20","side":"BUY","hash":"2af21c7e31f4e69c7200cb21652e68864658a5f4","best_bid":"0.999","best_ask":"1"},{"asset_id":"72709494218706655003179124592746636178529103451837436693660676934739929402705","price":"0.999","size":"20","side":"SELL","hash":"ec5e5ad1a2ec9b0998516fcfe84b0587bb2a9a79","best_bid":"0","best_ask":"0.001"}],"timestamp":"1788920376755","event_type":"price_change"}}
{"ts_mono_ns":10862940724551,"ts_wall_ns":1788920377505205694,"fonte":"poly_ws","payload":{"market":"0xf250e9cda122a88bffb973a0c10d67302f06c4d6d2a7a998bbd514c9b783cb9c","price_changes":[{"asset_id":"25904534922361021063199958329408275661746575318235828101794830786745156915675","price":"0.61","size":"1762","side":"BUY","hash":"3a732e5abd3bfa6ebbd44972659a4b14003ecb08","best_bid":"0.66","best_ask":"0.67"},{"asset_id":"30628628256922129361568138552829834868125997804575067220632439143002067301195","price":"0.39","size":"1762","side":"SELL","hash":"bea5209879c83ff6efc6a70aef794a328e283b4a","best_bid":"0.33","best_ask":"0.34"}],"timestamp":"1788920376756","event_type":"price_change"}}
{"ts_mono_ns":10862940743703,"ts_wall_ns":1788920377505224845,"fonte":"poly_ws","payload":{"market":"0x583e8a11679a33294b1e20a89374e4742961f151f1f05c9a0c1eb34883a7538f","price_changes":[{"asset_id":"46179897111767575621067600626085063615255126374895750367620822995125397577982","price":"0.99","size":"17457","side":"BUY","hash":"b7e29f206c56eac5a48f10708b5ed89ddd028741","best_bid":"0.999","best_ask":"1"},{"asset_id":"72709494218706655003179124592746636178529103451837436693660676934739929402705","price":"0.01","size":"17457","side":"SELL","hash":"6dd7dc74bb0e44276d6c3d5683f7f3a4fef15708","best_bid":"0","best_ask":"0.001"}],"timestamp":"1788920376760","event_type":"price_change"}}
{"ts_mono_ns":10862940768815,"ts_wall_ns":1788920377505250000,"fonte":"poly_ws","payload":{"market":"0xf250e9cda122a88bffb973a0c10d67302f06c4d6d2a7a998bbd514c9b783cb9c","price_changes":[{"asset_id":"30628628256922129361568138552829834868125997804575067220632439143002067301195","price":"0.27","size":"342.11","side":"BUY","hash":"f85afa527c4f0c7ed934f14cf940e917b624da9d","best_bid":"0.33","best_ask":"0.34"},{"asset_id":"25904534922361021063199958329408275661746575318235828101794830786745156915675","price":"0.73","size":"342.11","side":"SELL","hash":"759cb8afb58886b618a323ffe0aebc383268260d","best_bid":"0.66","best_ask":"0.67"}],"timestamp":"1788920376763","event_type":"price_change"}}
{"ts_mono_ns":10862940788728,"ts_wall_ns":1788920377505269870,"fonte":"poly_ws","payload":{"market":"0x64525468c38c020b83980bb3661be273102ad3f34ba80d707d30f97d9886c81c","price_changes":[{"asset_id":"46262863008926656059863048074084142778448142656654450709250567525401921137815","price":"0.01","size":"494.53","side":"BUY","hash":"9c1b8e5350e1f66210c915e7a45e547ccc529482","best_bid":"0.999","best_ask":"1"},{"asset_id":"38757477958501548946411732768268448708016318667797233629101626869770403495012","price":"0.99","size":"494.53","side":"SELL","hash":"2b96ad2dca0250a2f1566429c159de6772662bdc","best_bid":"0","best_ask":"0.001"}],"timestamp":"1788920376764","event_type":"price_change"}}
{"ts_mono_ns":10862940813671,"ts_wall_ns":1788920377505294813,"fonte":"poly_ws","payload":{"market":"0x583e8a11679a33294b1e20a89374e4742961f151f1f05c9a0c1eb34883a7538f","price_changes":[{"asset_id":"46179897111767575621067600626085063615255126374895750367620822995125397577982","price":"0.01","size":"3629.08","side":"BUY","hash":"0dd24948300334bacbe2ccb37509e0df1de12155","best_bid":"0.999","best_ask":"1"},{"asset_id":"72709494218706655003179124592746636178529103451837436693660676934739929402705","price":"0.99","size":"3629.08","side":"SELL","hash":"ef01d49bb76c7734a13e9c4dc95012553900227a","best_bid":"0","best_ask":"0.001"}],"timestamp":"1788920376765","event_type":"price_change"}}
{"ts_mono_ns":10862940836543,"ts_wall_ns":1788920377505317685,"fonte":"poly_ws","payload":{"market":"0xf250e9cda122a88bffb973a0c10d67302f06c4d6d2a7a998bbd514c9b783cb9c","price_changes":[{"asset_id":"25904534922361021063199958329408275661746575318235828101794830786745156915675","price":"0.01","size":"1809.75","side":"BUY","hash":"1a84c38f5d43ba5f39e0bab6224dafa0d6babef2","best_bid":"0.66","best_ask":"0.67"},{"asset_id":"30628628256922129361568138552829834868125997804575067220632439143002067301195","price":"0.99","size":"1809.75","side":"SELL","hash":"d96f7f46d6e209676a9e7b8fe0fbf2401381e9fd","best_bid":"0.33","best_ask":"0.34"}],"timestamp":"1788920376766","event_type":"price_change"}}
{"ts_mono_ns":10862940855821,"ts_wall_ns":1788920377505336963,"fonte":"poly_ws","payload":{"market":"0x6db86d879d6de1f8ed59e4e83b2a37d72f4599f4c80ed6f96dbc0005fb9f1ac8","price_changes":[{"asset_id":"12208676729015978316770585339908065400843685785594905658036146242748494746320","price":"0.01","size":"3539.76","side":"BUY","hash":"ca70cdc54875bb641186cbbb92a509d687a3f579","best_bid":"0.74","best_ask":"0.75"},{"asset_id":"30870479713256640338083935757610569169860141841648034347580579440853611443190","price":"0.99","size":"3539.76","side":"SELL","hash":"c60f9b71429d01ccf833d7fe7c9de2d447efe4c1","best_bid":"0.25","best_ask":"0.26"}],"timestamp":"1788920376767","event_type":"price_change"}}
{"ts_mono_ns":10862940873831,"ts_wall_ns":1788920377505355016,"fonte":"poly_ws","payload":{"market":"0x583e8a11679a33294b1e20a89374e4742961f151f1f05c9a0c1eb34883a7538f","price_changes":[{"asset_id":"46179897111767575621067600626085063615255126374895750367620822995125397577982","price":"0.01","size":"3635.08","side":"BUY","hash":"3f0576d6633a5c3c6808bc809fb8c53aa22841cf","best_bid":"0.999","best_ask":"1"},{"asset_id":"72709494218706655003179124592746636178529103451837436693660676934739929402705","price":"0.99","size":"3635.08","side":"SELL","hash":"31fb4163b7286b5afa14009ca9945756db03d0a1","best_bid":"0","best_ask":"0.001"}],"timestamp":"1788920376767","event_type":"price_change"}}
{"ts_mono_ns":10862940917587,"ts_wall_ns":1788920377505398772,"fonte":"poly_ws","payload":{"market":"0x73fd6c72d0bf8220003943b6e2b41292b8cd4d97c27314db06735789b59e9d09","price_changes":[{"asset_id":"113917660431940170818498786968146153783642292134565871228813850528518440127962","price":"0.37","size":"24","side":"BUY","hash":"7dede957b28b9b62501048e74d85e6ee652bbfed","best_bid":"0.37","best_ask":"0.38"},{"asset_id":"84363210919223921947447886444210431825911105421883946794723950657543270560538","price":"0.63","size":"24","side":"SELL","hash":"4277a33390e129b0c00fd30ea318d3107eb78a76","best_bid":"0.62","best_ask":"0.63"}],"timestamp":"1788920376769","event_type":"price_change"}}
{"ts_mono_ns":10862940939148,"ts_wall_ns":1788920377505420291,"fonte":"poly_ws","payload":{"market":"0xf250e9cda122a88bffb973a0c10d67302f06c4d6d2a7a998bbd514c9b783cb9c","price_changes":[{"asset_id":"25904534922361021063199958329408275661746575318235828101794830786745156915675","price":"0.01","size":"1814.75","side":"BUY","hash":"c1390b533c4cae72fa017fbb6c1cbfb04d30eaac","best_bid":"0.66","best_ask":"0.67"},{"asset_id":"30628628256922129361568138552829834868125997804575067220632439143002067301195","price":"0.99","size":"1814.75","side":"SELL","hash":"7eac430b97399821cf31462023034bd05a250e56","best_bid":"0.33","best_ask":"0.34"}],"timestamp":"1788920376771","event_type":"price_change"}}
{"ts_mono_ns":10862940958131,"ts_wall_ns":1788920377505439273,"fonte":"poly_ws","payload":{"market":"0x583e8a11679a33294b1e20a89374e4742961f151f1f05c9a0c1eb34883a7538f","price_changes":[{"asset_id":"46179897111767575621067600626085063615255126374895750367620822995125397577982","price":"0.01","size":"3640.08","side":"BUY","hash":"f4255d99d115df708b50e3f61025de4f2698df09","best_bid":"0.999","best_ask":"1"},{"asset_id":"72709494218706655003179124592746636178529103451837436693660676934739929402705","price":"0.99","size":"3640.08","side":"SELL","hash":"f3ba2b9720e5eca89bafb497055303eefb6244ed","best_bid":"0","best_ask":"0.001"}],"timestamp":"1788920376774","event_type":"price_change"}}
{"ts_mono_ns":10862940980749,"ts_wall_ns":1788920377505461891,"fonte":"poly_ws","payload":{"market":"0x73fd6c72d0bf8220003943b6e2b41292b8cd4d97c27314db06735789b59e9d09","price_changes":[{"asset_id":"84363210919223921947447886444210431825911105421883946794723950657543270560538","price":"0.01","size":"591.93","side":"BUY","hash":"b04ce157643f563a6fa79f636c622278b1519fc5","best_bid":"0.62","best_ask":"0.63"},{"asset_id":"113917660431940170818498786968146153783642292134565871228813850528518440127962","price":"0.99","size":"591.93","side":"SELL","hash":"2b224043048e669599ea8694561a97df3c909301","best_bid":"0.37","best_ask":"0.38"}],"timestamp":"1788920376774","event_type":"price_change"}}
{"ts_mono_ns":10862941000661,"ts_wall_ns":1788920377505481804,"fonte":"poly_ws","payload":{"market":"0xf250e9cda122a88bffb973a0c10d67302f06c4d6d2a7a998bbd514c9b783cb9c","price_changes":[{"asset_id":"30628628256922129361568138552829834868125997804575067220632439143002067301195","price":"0.01","size":"1918.75","side":"BUY","hash":"ea83ec6fa63bfca40c6545058addb4b6a203a61e","best_bid":"0.33","best_ask":"0.34"},{"asset_id":"25904534922361021063199958329408275661746575318235828101794830786745156915675","price":"0.99","size":"1918.75","side":"SELL","hash":"c6f7858e5a9abb43cc2930f379de9cf527494d2b","best_bid":"0.66","best_ask":"0.67"}],"timestamp":"1788920376778","event_type":"price_change"}}
{"ts_mono_ns":10862941028268,"ts_wall_ns":1788920377505509411,"fonte":"poly_ws","payload":{"market":"0xf250e9cda122a88bffb973a0c10d67302f06c4d6d2a7a998bbd514c9b783cb9c","price_changes":[{"asset_id":"25904534922361021063199958329408275661746575318235828101794830786745156915675","price":"0.01","size":"1809.75","side":"BUY","hash":"8ea2ab54add0343ff4a27a1b40f969641bbfb2ea","best_bid":"0.66","best_ask":"0.67"},{"asset_id":"30628628256922129361568138552829834868125997804575067220632439143002067301195","price":"0.99","size":"1809.75","side":"SELL","hash":"0faf0dfc6f56972d4e562cb30894f3301947fc3c","best_bid":"0.33","best_ask":"0.34"}],"timestamp":"1788920376784","event_type":"price_change"}}
{"ts_mono_ns":10862941047250,"ts_wall_ns":1788920377505528393,"fonte":"poly_ws","payload":{"market":"0x583e8a11679a33294b1e20a89374e4742961f151f1f05c9a0c1eb34883a7538f","price_changes":[{"asset_id":"46179897111767575621067600626085063615255126374895750367620822995125397577982","price":"0.01","size":"3635.08","side":"BUY","hash":"d264ab1c61dba317e9810d025149317a92f7e2e5","best_bid":"0.999","best_ask":"1"},{"asset_id":"72709494218706655003179124592746636178529103451837436693660676934739929402705","price":"0.99","size":"3635.08","side":"SELL","hash":"b1ba524e64b6c438a84739efb1706a19ee534dcc","best_bid":"0","best_ask":"0.001"}],"timestamp":"1788920376785","event_type":"price_change"}}
{"ts_mono_ns":10862941070545,"ts_wall_ns":1788920377505551687,"fonte":"poly_ws","payload":{"market":"0x64525468c38c020b83980bb3661be273102ad3f34ba80d707d30f97d9886c81c","price_changes":[{"asset_id":"46262863008926656059863048074084142778448142656654450709250567525401921137815","price":"0.01","size":"489.53","side":"BUY","hash":"91e75d2d57accf09e5261ad4a2ce139f58389c35","best_bid":"0.999","best_ask":"1"},{"asset_id":"38757477958501548946411732768268448708016318667797233629101626869770403495012","price":"0.99","size":"489.53","side":"SELL","hash":"e5c87c4c77c289005cb1abc43c8f8818a3d8ab63","best_bid":"0","best_ask":"0.001"}],"timestamp":"1788920376784","event_type":"price_change"}}
{"ts_mono_ns":10862941093374,"ts_wall_ns":1788920377505574517,"fonte":"poly_ws","payload":{"market":"0x6db86d879d6de1f8ed59e4e83b2a37d72f4599f4c80ed6f96dbc0005fb9f1ac8","price_changes":[{"asset_id":"12208676729015978316770585339908065400843685785594905658036146242748494746320","price":"0.01","size":"3534.76","side":"BUY","hash":"a31207ac1d7f23e4ba1f48457bec881334b054f3","best_bid":"0.74","best_ask":"0.75"},{"asset_id":"30870479713256640338083935757610569169860141841648034347580579440853611443190","price":"0.99","size":"3534.76","side":"SELL","hash":"50796a6dae704ac54f157fa31b669da155b11870","best_bid":"0.25","best_ask":"0.26"}],"timestamp":"1788920376786","event_type":"price_change"}}
{"ts_mono_ns":10862941110539,"ts_wall_ns":1788920377505591681,"fonte":"poly_ws","payload":{"market":"0x583e8a11679a33294b1e20a89374e4742961f151f1f05c9a0c1eb34883a7538f","price_changes":[{"asset_id":"46179897111767575621067600626085063615255126374895750367620822995125397577982","price":"0.99","size":"17451.99","side":"BUY","hash":"c2a2efa5d775e43addbaee701fea8f0ccfb4b857","best_bid":"0.999","best_ask":"1"},{"asset_id":"72709494218706655003179124592746636178529103451837436693660676934739929402705","price":"0.01","size":"17451.99","side":"SELL","hash":"0001534b9d8d2553a063ac0bb8ffe3fcd46124ca","best_bid":"0","best_ask":"0.001"}],"timestamp":"1788920376789","event_type":"price_change"}}
{"ts_mono_ns":10862941133876,"ts_wall_ns":1788920377505615018,"fonte":"poly_ws","payload":{"market":"0x583e8a11679a33294b1e20a89374e4742961f151f1f05c9a0c1eb34883a7538f","price_changes":[{"asset_id":"46179897111767575621067600626085063615255126374895750367620822995125397577982","price":"0.01","size":"3629.08","side":"BUY","hash":"be28bf25954df54d9204e815f0f5665c29e96d57","best_bid":"0.999","best_ask":"1"},{"asset_id":"72709494218706655003179124592746636178529103451837436693660676934739929402705","price":"0.99","size":"3629.08","side":"SELL","hash":"0402d98c1c18156db746317e2821e7a41b55c8dc","best_bid":"0","best_ask":"0.001"}],"timestamp":"1788920376791","event_type":"price_change"}}
{"ts_mono_ns":10862941177886,"ts_wall_ns":1788920377505659028,"fonte":"poly_ws","payload":{"market":"0x73fd6c72d0bf8220003943b6e2b41292b8cd4d97c27314db06735789b59e9d09","price_changes":[{"asset_id":"113917660431940170818498786968146153783642292134565871228813850528518440127962","price":"0.37","size":"0","side":"BUY","hash":"485dafbcc50b633b663b4506d796600c93878cd3","best_bid":"0.36","best_ask":"0.38"},{"asset_id":"84363210919223921947447886444210431825911105421883946794723950657543270560538","price":"0.63","size":"0","side":"SELL","hash":"b1f68b153432cca9218ec73f864eaa014ca61c37","best_bid":"0.62","best_ask":"0.64"}],"timestamp":"1788920376793","event_type":"price_change"}}
{"ts_mono_ns":10862941195811,"ts_wall_ns":1788920377505676954,"fonte":"poly_ws","payload":{"market":"0xf250e9cda122a88bffb973a0c10d67302f06c4d6d2a7a998bbd514c9b783cb9c","price_changes":[{"asset_id":"25904534922361021063199958329408275661746575318235828101794830786745156915675","price":"0.62","size":"6564","side":"BUY","hash":"892c4acba1500e25f99adaa42d825898b3df23e6","best_bid":"0.66","best_ask":"0.67"},{"asset_id":"30628628256922129361568138552829834868125997804575067220632439143002067301195","price":"0.38","size":"6564","side":"SELL","hash":"12fa1c90e22b8a293a05c96f3fbfb22ded925e4e","best_bid":"0.33","best_ask":"0.34"}],"timestamp":"1788920376792","event_type":"price_change"}}
{"ts_mono_ns":10862941214624,"ts_wall_ns":1788920377505695809,"fonte":"poly_ws","payload":{"market":"0xf250e9cda122a88bffb973a0c10d67302f06c4d6d2a7a998bbd514c9b783cb9c","price_changes":[{"asset_id":"25904534922361021063199958329408275661746575318235828101794830786745156915675","price":"0.01","size":"1804.75","side":"BUY","hash":"d4ffa59fbd29d6169a8a245bbc1bee1d69491233","best_bid":"0.66","best_ask":"0.67"},{"asset_id":"30628628256922129361568138552829834868125997804575067220632439143002067301195","price":"0.99","size":"1804.75","side":"SELL","hash":"96cd2d6d696d3d2e89339bc174d8434f514a8b37","best_bid":"0.33","best_ask":"0.34"}],"timestamp":"1788920376793","event_type":"price_change"}}
{"ts_mono_ns":10862941232761,"ts_wall_ns":1788920377505713904,"fonte":"poly_ws","payload":{"market":"0xf250e9cda122a88bffb973a0c10d67302f06c4d6d2a7a998bbd514c9b783cb9c","price_changes":[{"asset_id":"25904534922361021063199958329408275661746575318235828101794830786745156915675","price":"0.61","size":"2063","side":"BUY","hash":"89f15f47227c7dac235cf595581f72b081190ae6","best_bid":"0.66","best_ask":"0.67"},{"asset_id":"30628628256922129361568138552829834868125997804575067220632439143002067301195","price":"0.39","size":"2063","side":"SELL","hash":"1741a7b33edc9289d753d361dc8d82f17f22ae09","best_bid":"0.33","best_ask":"0.34"}],"timestamp":"1788920376793","event_type":"price_change"}}
{"ts_mono_ns":10862941250856,"ts_wall_ns":1788920377505731998,"fonte":"poly_ws","payload":{"market":"0x583e8a11679a33294b1e20a89374e4742961f151f1f05c9a0c1eb34883a7538f","price_changes":[{"asset_id":"46179897111767575621067600626085063615255126374895750367620822995125397577982","price":"0.01","size":"3624.08","side":"BUY","hash":"1efcb2f2b6778540e3c6c6eb2c7a93b2ff677673","best_bid":"0.999","best_ask":"1"},{"asset_id":"72709494218706655003179124592746636178529103451837436693660676934739929402705","price":"0.99","size":"3624.08","side":"SELL","hash":"4b561b741ccc07cd1f1f3ba5824b351e7df6b8dd","best_bid":"0","best_ask":"0.001"}],"timestamp":"1788920376798","event_type":"price_change"}}
{"ts_mono_ns":10862941273305,"ts_wall_ns":1788920377505754447,"fonte":"poly_ws","payload":{"market":"0x583e8a11679a33294b1e20a89374e4742961f151f1f05c9a0c1eb34883a7538f","price_changes":[{"asset_id":"46179897111767575621067600626085063615255126374895750367620822995125397577982","price":"0.01","size":"3629.08","side":"BUY","hash":"0bc76b10185fab292f9687c298ebef172d51792c","best_bid":"0.999","best_ask":"1"},{"asset_id":"72709494218706655003179124592746636178529103451837436693660676934739929402705","price":"0.99","size":"3629.08","side":"SELL","hash":"744c2e32ffc6c3108d484528b1debd4133ef47f1","best_bid":"0","best_ask":"0.001"}],"timestamp":"1788920376798","event_type":"price_change"}}
{"ts_mono_ns":10862941295584,"ts_wall_ns":1788920377505776769,"fonte":"poly_ws","payload":{"market":"0x583e8a11679a33294b1e20a89374e4742961f151f1f05c9a0c1eb34883a7538f","price_changes":[{"asset_id":"46179897111767575621067600626085063615255126374895750367620822995125397577982","price":"0.01","size":"3634.08","side":"BUY","hash":"0fa63c0e385c39cffbf39442d397d504ede85d6d","best_bid":"0.999","best_ask":"1"},{"asset_id":"72709494218706655003179124592746636178529103451837436693660676934739929402705","price":"0.99","size":"3634.08","side":"SELL","hash":"9c669329418496b4e42ff6dac955d31ce218df6a","best_bid":"0","best_ask":"0.001"}],"timestamp":"1788920376799","event_type":"price_change"}}
{"ts_mono_ns":10862941317780,"ts_wall_ns":1788920377505798922,"fonte":"poly_ws","payload":{"market":"0x73fd6c72d0bf8220003943b6e2b41292b8cd4d97c27314db06735789b59e9d09","price_changes":[{"asset_id":"84363210919223921947447886444210431825911105421883946794723950657543270560538","price":"0.01","size":"586.93","side":"BUY","hash":"58a4223641885e2f640c2f47e9de970866ba0bc9","best_bid":"0.62","best_ask":"0.64"},{"asset_id":"113917660431940170818498786968146153783642292134565871228813850528518440127962","price":"0.99","size":"586.93","side":"SELL","hash":"642f33393f5e7e493d0240dd3f16cb2cbb5ea376","best_bid":"0.36","best_ask":"0.38"}],"timestamp":"1788920376800","event_type":"price_change"}}
{"ts_mono_ns":10862941337692,"ts_wall_ns":1788920377505818835,"fonte":"poly_ws","payload":{"market":"0x583e8a11679a33294b1e20a89374e4742961f151f1f05c9a0c1eb34883a7538f","price_changes":[{"asset_id":"46179897111767575621067600626085063615255126374895750367620822995125397577982","price":"0.01","size":"3639.08","side":"BUY","hash":"8c458d4e23010b2c1cb56bbc316e8121f8eaa392","best_bid":"0.999","best_ask":"1"},{"asset_id":"72709494218706655003179124592746636178529103451837436693660676934739929402705","price":"0.99","size":"3639.08","side":"SELL","hash":"c6cbde16a70c2b1e04169ae89a091189f1cf20ec","best_bid":"0","best_ask":"0.001"}],"timestamp":"1788920376800","event_type":"price_change"}}
{"ts_mono_ns":10862941360310,"ts_wall_ns":1788920377505841453,"fonte":"poly_ws","payload":{"market":"0x583e8a11679a33294b1e20a89374e4742961f151f1f05c9a0c1eb34883a7538f","price_changes":[{"asset_id":"72709494218706655003179124592746636178529103451837436693660676934739929402705","price":"0.03","size":"179.66","side":"SELL","hash":"90be7e51ae552aa944238370291dab4c358fe21a","best_bid":"0","best_ask":"0.001"},{"asset_id":"46179897111767575621067600626085063615255126374895750367620822995125397577982","price":"0.97","size":"179.66","side":"BUY","hash":"90c005674f78ec58cf7bfb9a03b24858b5fe8d0c","best_bid":"0.999","best_ask":"1"}],"timestamp":"1788920376804","event_type":"price_change"}}
{"ts_mono_ns":10862941383140,"ts_wall_ns":1788920377505864282,"fonte":"poly_ws","payload":{"market":"0xf250e9cda122a88bffb973a0c10d67302f06c4d6d2a7a998bbd514c9b783cb9c","price_changes":[{"asset_id":"25904534922361021063199958329408275661746575318235828101794830786745156915675","price":"0.01","size":"1799.75","side":"BUY","hash":"777db49fa8fefa8f0214b9f737f8a5f398b22e80","best_bid":"0.66","best_ask":"0.67"},{"asset_id":"30628628256922129361568138552829834868125997804575067220632439143002067301195","price":"0.99","size":"1799.75","side":"SELL","hash":"2c9bb722bf109dc8d20d53eb3d7a2b70b23e4b26","best_bid":"0.33","best_ask":"0.34"}],"timestamp":"1788920376808","event_type":"price_change"}}
{"ts_mono_ns":10862941421654,"ts_wall_ns":1788920377505902796,"fonte":"poly_ws","payload":{"market":"0x73fd6c72d0bf8220003943b6e2b41292b8cd4d97c27314db06735789b59e9d09","price_changes":[{"asset_id":"113917660431940170818498786968146153783642292134565871228813850528518440127962","price":"0.37","size":"24","side":"BUY","hash":"24a02804eeab6b59f7d1cc11c931c5e293a4b100","best_bid":"0.37","best_ask":"0.38"},{"asset_id":"84363210919223921947447886444210431825911105421883946794723950657543270560538","price":"0.63","size":"24","side":"SELL","hash":"4246bcc360705aad35b71444a4605173a8ee4a12","best_bid":"0.62","best_ask":"0.63"}],"timestamp":"1788920376814","event_type":"price_change"}}
{"ts_mono_ns":10862941439114,"ts_wall_ns":1788920377505920257,"fonte":"poly_ws","payload":{"market":"0x583e8a11679a33294b1e20a89374e4742961f151f1f05c9a0c1eb34883a7538f","price_changes":[{"asset_id":"72709494218706655003179124592746636178529103451837436693660676934739929402705","price":"0.02","size":"353","side":"SELL","hash":"1cca2f1c05d7568e1f1869539034294bccf497ec","best_bid":"0","best_ask":"0.001"},{"asset_id":"46179897111767575621067600626085063615255126374895750367620822995125397577982","price":"0.98","size":"353","side":"BUY","hash":"fbf56aa1467bd7a6827157953119eacdbb694880","best_bid":"0.999","best_ask":"1"}],"timestamp":"1788920376816","event_type":"price_change"}}
{"ts_mono_ns":10862941461944,"ts_wall_ns":1788920377505943129,"fonte":"poly_ws","payload":{"market":"0xf250e9cda122a88bffb973a0c10d67302f06c4d6d2a7a998bbd514c9b783cb9c","price_changes":[{"asset_id":"30628628256922129361568138552829834868125997804575067220632439143002067301195","price":"0.27","size":"532.11","side":"BUY","hash":"9d578f9ed6780dca70c1d9d5591f61187106736b","best_bid":"0.33","best_ask":"0.34"},{"asset_id":"25904534922361021063199958329408275661746575318235828101794830786745156915675","price":"0.73","size":"532.11","side":"SELL","hash":"8e8634918556b9e9e745fda323576c23b02ec86a","best_bid":"0.66","best_ask":"0.67"}],"timestamp":"1788920376820","event_type":"price_change"}}
{"ts_mono_ns":10862941480715,"ts_wall_ns":1788920377505961857,"fonte":"poly_ws","payload":{"market":"0xf250e9cda122a88bffb973a0c10d67302f06c4d6d2a7a998bbd514c9b783cb9c","price_changes":[{"asset_id":"25904534922361021063199958329408275661746575318235828101794830786745156915675","price":"0.62","size":"6457","side":"BUY","hash":"bf8828743b3e8dcc460ab63697e98c2175d9a1bb","best_bid":"0.66","best_ask":"0.67"},{"asset_id":"30628628256922129361568138552829834868125997804575067220632439143002067301195","price":"0.38","size":"6457","side":"SELL","hash":"14849c32374c8935c0d6f228db0c7a6c66bc71d0","best_bid":"0.33","best_ask":"0.34"}],"timestamp":"1788920376820","event_type":"price_change"}}
{"ts_mono_ns":10862941499782,"ts_wall_ns":1788920377505980924,"fonte":"poly_ws","payload":{"market":"0x583e8a11679a33294b1e20a89374e4742961f151f1f05c9a0c1eb34883a7538f","price_changes":[{"asset_id":"46179897111767575621067600626085063615255126374895750367620822995125397577982","price":"0.001","size":"15","side":"BUY","hash":"117240cf9df57c1b4b202a5a6bbb86e008cb1292","best_bid":"0.999","best_ask":"1"},{"asset_id":"72709494218706655003179124592746636178529103451837436693660676934739929402705","price":"0.999","size":"15","side":"SELL","hash":"2fe2eaf3e1bf29f085de2df0de6097f8603710fb","best_bid":"0","best_ask":"0.001"}],"timestamp":"1788920376824","event_type":"price_change"}}
{"ts_mono_ns":10862941522822,"ts_wall_ns":1788920377506004007,"fonte":"poly_ws","payload":{"market":"0x583e8a11679a33294b1e20a89374e4742961f151f1f05c9a0c1eb34883a7538f","price_changes":[{"asset_id":"46179897111767575621067600626085063615255126374895750367620822995125397577982","price":"0.01","size":"3634.08","side":"BUY","hash":"3ca1048e03a4388824cbc8af9e07a20cd9ac103b","best_bid":"0.999","best_ask":"1"},{"asset_id":"72709494218706655003179124592746636178529103451837436693660676934739929402705","price":"0.99","size":"3634.08","side":"SELL","hash":"115c1a1608d40307cb05f2b789eb86c15779b844","best_bid":"0","best_ask":"0.001"}],"timestamp":"1788920376829","event_type":"price_change"}}
{"ts_mono_ns":10862941545736,"ts_wall_ns":1788920377506026879,"fonte":"poly_ws","payload":{"market":"0x1cdc3a0eb5c98a05d22f6506a499c9bb72215136ccc70117f4a3df0e270565db","price_changes":[{"asset_id":"84416789117991784246230849637761211585972186658544928299333252960108694363684","price":"0.4","size":"104","side":"BUY","hash":"b0107459691b0c4826e6cc304a9159cc6a6cd63e","best_bid":"0.45","best_ask":"0.48"},{"asset_id":"48837808639818344506241107387894855683952183911807769939475302802205691316596","price":"0.6","size":"104","side":"SELL","hash":"0af1f0998d0fd5037c34ee7bb2939b447326fe6b","best_bid":"0.52","best_ask":"0.55"}],"timestamp":"1788920376830","event_type":"price_change"}}
{"ts_mono_ns":10862941565353,"ts_wall_ns":1788920377506046495,"fonte":"poly_ws","payload":{"market":"0x1cdc3a0eb5c98a05d22f6506a499c9bb72215136ccc70117f4a3df0e270565db","price_changes":[{"asset_id":"84416789117991784246230849637761211585972186658544928299333252960108694363684","price":"0.38","size":"75","side":"BUY","hash":"92c16f27cdd3345570dd5b0af361e8607fbd5737","best_bid":"0.45","best_ask":"0.48"},{"asset_id":"48837808639818344506241107387894855683952183911807769939475302802205691316596","price":"0.62","size":"75","side":"SELL","hash":"13a82f0f6f1597bc9319e4c344b1b4b6b82400aa","best_bid":"0.52","best_ask":"0.55"}],"timestamp":"1788920376830","event_type":"price_change"}}
{"ts_mono_ns":10862941583659,"ts_wall_ns":1788920377506064801,"fonte":"poly_ws","payload":{"market":"0x1cdc3a0eb5c98a05d22f6506a499c9bb72215136ccc70117f4a3df0e270565db","price_changes":[{"asset_id":"84416789117991784246230849637761211585972186658544928299333252960108694363684","price":"0.39","size":"75","side":"BUY","hash":"2215c4e57f5ca884470561d6a4fc38da4a31d890","best_bid":"0.45","best_ask":"0.48"},{"asset_id":"48837808639818344506241107387894855683952183911807769939475302802205691316596","price":"0.61","size":"75","side":"SELL","hash":"2ebc9de6661ed3b52cefbba8bfe47b95c8499499","best_bid":"0.52","best_ask":"0.55"}],"timestamp":"1788920376831","event_type":"price_change"}}
{"ts_mono_ns":10862941601457,"ts_wall_ns":1788920377506082600,"fonte":"poly_ws","payload":{"market":"0xf250e9cda122a88bffb973a0c10d67302f06c4d6d2a7a998bbd514c9b783cb9c","price_changes":[{"asset_id":"25904534922361021063199958329408275661746575318235828101794830786745156915675","price":"0.01","size":"1794.75","side":"BUY","hash":"3f10e9ec916aaf418f2ec7f08bf3cf872f67f9db","best_bid":"0.66","best_ask":"0.67"},{"asset_id":"30628628256922129361568138552829834868125997804575067220632439143002067301195","price":"0.99","size":"1794.75","side":"SELL","hash":"a7b2fb890feb4de1a6ae6e2f266d45c7da7a47d0","best_bid":"0.33","best_ask":"0.34"}],"timestamp":"1788920376837","event_type":"price_change"}}
{"ts_mono_ns":10862941619932,"ts_wall_ns":1788920377506101075,"fonte":"poly_ws","payload":{"market":"0xf250e9cda122a88bffb973a0c10d67302f06c4d6d2a7a998bbd514c9b783cb9c","price_changes":[{"asset_id":"30628628256922129361568138552829834868125997804575067220632439143002067301195","price":"0.28","size":"2156","side":"BUY","hash":"afb26574c28aa452c904cd1aec033168303c8e41","best_bid":"0.33","best_ask":"0.34"},{"asset_id":"25904534922361021063199958329408275661746575318235828101794830786745156915675","price":"0.72","size":"2156","side":"SELL","hash":"e44a1573e28c75fed902539315d40c318133357e","best_bid":"0.66","best_ask":"0.67"}],"timestamp":"1788920376844","event_type":"price_change"}}
{"ts_mono_ns":10862941658151,"ts_wall_ns":1788920377506139293,"fonte":"poly_ws","payload":{"market":"0x73fd6c72d0bf8220003943b6e2b41292b8cd4d97c27314db06735789b59e9d09","price_changes":[{"asset_id":"113917660431940170818498786968146153783642292134565871228813850528518440127962","price":"0.37","size":"0","side":"BUY","hash":"152f769f32074944409124934c2d5c2625096656","best_bid":"0.36","best_ask":"0.38"},{"asset_id":"84363210919223921947447886444210431825911105421883946794723950657543270560538","price":"0.63","size":"0","side":"SELL","hash":"f9afc6ee4ae80ff399df173d2b152839e6c544ba","best_bid":"0.62","best_ask":"0.64"}],"timestamp":"1788920376849","event_type":"price_change"}}
{"ts_mono_ns":10862941677978,"ts_wall_ns":1788920377506159121,"fonte":"poly_ws","payload":{"market":"0x583e8a11679a33294b1e20a89374e4742961f151f1f05c9a0c1eb34883a7538f","price_changes":[{"asset_id":"46179897111767575621067600626085063615255126374895750367620822995125397577982","price":"0.01","size":"3629.08","side":"BUY","hash":"12d5c1177905ab39150b788140089781f50cc055","best_bid":"0.999","best_ask":"1"},{"asset_id":"72709494218706655003179124592746636178529103451837436693660676934739929402705","price":"0.99","size":"3629.08","side":"SELL","hash":"14c00589c7af5cb5c199359fa52509c90bd0d56d","best_bid":"0","best_ask":"0.001"}],"timestamp":"1788920376857","event_type":"price_change"}}
{"ts_mono_ns":10862941700935,"ts_wall_ns":1788920377506182077,"fonte":"poly_ws","payload":{"market":"0x583e8a11679a33294b1e20a89374e4742961f151f1f05c9a0c1eb34883a7538f","price_changes":[{"asset_id":"46179897111767575621067600626085063615255126374895750367620822995125397577982","price":"0.01","size":"3635.08","side":"BUY","hash":"a4fa411fa2986882700ee986d7cb762221ebd42e","best_bid":"0.999","best_ask":"1"},{"asset_id":"72709494218706655003179124592746636178529103451837436693660676934739929402705","price":"0.99","size":"3635.08","side":"SELL","hash":"4aaaecab82f02066048a3ebce466ef4f44de8df0","best_bid":"0","best_ask":"0.001"}],"timestamp":"1788920376864","event_type":"price_change"}}
{"ts_mono_ns":10862941723933,"ts_wall_ns":1788920377506205076,"fonte":"poly_ws","payload":{"market":"0xf250e9cda122a88bffb973a0c10d67302f06c4d6d2a7a998bbd514c9b783cb9c","price_changes":[{"asset_id":"25904534922361021063199958329408275661746575318235828101794830786745156915675","price":"0.01","size":"1789.75","side":"BUY","hash":"44d6aa0ec141b4b8db32a0fd053d767720a5240c","best_bid":"0.66","best_ask":"0.67"},{"asset_id":"30628628256922129361568138552829834868125997804575067220632439143002067301195","price":"0.99","size":"1789.75","side":"SELL","hash":"27e5eec762b7cb08abbbc1db213407facdf5a806","best_bid":"0.33","best_ask":"0.34"}],"timestamp":"1788920376866","event_type":"price_change"}}
{"ts_mono_ns":10862941742450,"ts_wall_ns":1788920377506223593,"fonte":"poly_ws","payload":{"market":"0xf250e9cda122a88bffb973a0c10d67302f06c4d6d2a7a998bbd514c9b783cb9c","price_changes":[{"asset_id":"30628628256922129361568138552829834868125997804575067220632439143002067301195","price":"0.26","size":"171","side":"BUY","hash":"98dd62df19cfa410b985f3c5db01975d0c94f7c3","best_bid":"0.33","best_ask":"0.34"},{"asset_id":"25904534922361021063199958329408275661746575318235828101794830786745156915675","price":"0.74","size":"171","side":"SELL","hash":"0e904cd95f39229aa5cd4bbdd6e3063ab1dc1ce6","best_bid":"0.66","best_ask":"0.67"}],"timestamp":"1788920376868","event_type":"price_change"}}
{"ts_mono_ns":10862941760756,"ts_wall_ns":1788920377506241899,"fonte":"poly_ws","payload":{"market":"0xf250e9cda122a88bffb973a0c10d67302f06c4d6d2a7a998bbd514c9b783cb9c","price_changes":[{"asset_id":"25904534922361021063199958329408275661746575318235828101794830786745156915675","price":"0.53","size":"165","side":"BUY","hash":"0e904cd95f39229aa5cd4bbdd6e3063ab1dc1ce6","best_bid":"0.66","best_ask":"0.67"},{"asset_id":"30628628256922129361568138552829834868125997804575067220632439143002067301195","price":"0.47","size":"165","side":"SELL","hash":"98dd62df19cfa410b985f3c5db01975d0c94f7c3","best_bid":"0.33","best_ask":"0.34"}],"timestamp":"1788920376868","event_type":"price_change"}}
{"ts_mono_ns":10862941788701,"ts_wall_ns":1788920377506269844,"fonte":"poly_ws","payload":{"market":"0xf250e9cda122a88bffb973a0c10d67302f06c4d6d2a7a998bbd514c9b783cb9c","price_changes":[{"asset_id":"25904534922361021063199958329408275661746575318235828101794830786745156915675","price":"0.62","size":"6527","side":"BUY","hash":"898ea0b5db5fd6bd5d3f7fee63282c4cb535456d","best_bid":"0.66","best_ask":"0.67"},{"asset_id":"30628628256922129361568138552829834868125997804575067220632439143002067301195","price":"0.38","size":"6527","side":"SELL","hash":"c5f25326164e11048e6fc9341d92c7cef4f393d7","best_bid":"0.33","best_ask":"0.34"}],"timestamp":"1788920376870","event_type":"price_change"}}
{"ts_mono_ns":10862941816858,"ts_wall_ns":1788920377506298000,"fonte":"poly_ws","payload":{"market":"0x73fd6c72d0bf8220003943b6e2b41292b8cd4d97c27314db06735789b59e9d09","price_changes":[{"asset_id":"113917660431940170818498786968146153783642292134565871228813850528518440127962","price":"0.37","size":"24","side":"BUY","hash":"46511d2f4bd72deb6a2e211061da15373129be56","best_bid":"0.37","best_ask":"0.38"},{"asset_id":"84363210919223921947447886444210431825911105421883946794723950657543270560538","price":"0.63","size":"24","side":"SELL","hash":"eb81f66d8cd02f0b7f9ddd234364252a57ff5229","best_bid":"0.62","best_ask":"0.63"}],"timestamp":"1788920376871","event_type":"price_change"}}
{"ts_mono_ns":10862941836009,"ts_wall_ns":1788920377506317194,"fonte":"poly_ws","payload":{"market":"0x73fd6c72d0bf8220003943b6e2b41292b8cd4d97c27314db06735789b59e9d09","price_changes":[{"asset_id":"113917660431940170818498786968146153783642292134565871228813850528518440127962","price":"0.33","size":"121","side":"BUY","hash":"19239d0d45dafeb554dc36f8d50dc35c4fef6e38","best_bid":"0.37","best_ask":"0.38"},{"asset_id":"84363210919223921947447886444210431825911105421883946794723950657543270560538","price":"0.67","size":"121","side":"SELL","hash":"19155b2485bcab941fec3029ac9d82fb62249bed","best_bid":"0.62","best_ask":"0.63"}],"timestamp":"1788920376873","event_type":"price_change"}}
{"ts_mono_ns":10862941854907,"ts_wall_ns":1788920377506336049,"fonte":"poly_ws","payload":{"market":"0xf250e9cda122a88bffb973a0c10d67302f06c4d6d2a7a998bbd514c9b783cb9c","price_changes":[{"asset_id":"30628628256922129361568138552829834868125997804575067220632439143002067301195","price":"0.29","size":"199","side":"BUY","hash":"e92536a38155e4139e2ec11d265ea1768ab8c909","best_bid":"0.33","best_ask":"0.34"},{"asset_id":"25904534922361021063199958329408275661746575318235828101794830786745156915675","price":"0.71","size":"199","side":"SELL","hash":"37b339c126d33e4cc1156903343d377179e24c26","best_bid":"0.66","best_ask":"0.67"}],"timestamp":"1788920376877","event_type":"price_change"}}
{"ts_mono_ns":10862941872790,"ts_wall_ns":1788920377506353933,"fonte":"poly_ws","payload":{"market":"0xf250e9cda122a88bffb973a0c10d67302f06c4d6d2a7a998bbd514c9b783cb9c","price_changes":[{"asset_id":"25904534922361021063199958329408275661746575318235828101794830786745156915675","price":"0.62","size":"4297","side":"BUY","hash":"767d54b9cb841b316a6d1e74f28ae45ddaae18a0","best_bid":"0.66","best_ask":"0.67"},{"asset_id":"30628628256922129361568138552829834868125997804575067220632439143002067301195","price":"0.38","size":"4297","side":"SELL","hash":"163879242cee1eeaf308fff9058252cd50ad9188","best_bid":"0.33","best_ask":"0.34"}],"timestamp":"1788920376881","event_type":"price_change"}}
{"ts_mono_ns":10862941890673,"ts_wall_ns":1788920377506371816,"fonte":"poly_ws","payload":{"market":"0xf250e9cda122a88bffb973a0c10d67302f06c4d6d2a7a998bbd514c9b783cb9c","price_changes":[{"asset_id":"25904534922361021063199958329408275661746575318235828101794830786745156915675","price":"0.61","size":"1542","side":"BUY","hash":"767d54b9cb841b316a6d1e74f28ae45ddaae18a0","best_bid":"0.66","best_ask":"0.67"},{"asset_id":"30628628256922129361568138552829834868125997804575067220632439143002067301195","price":"0.39","size":"1542","side":"SELL","hash":"163879242cee1eeaf308fff9058252cd50ad9188","best_bid":"0.33","best_ask":"0.34"}],"timestamp":"1788920376881","event_type":"price_change"}}
{"ts_mono_ns":10862941908598,"ts_wall_ns":1788920377506389741,"fonte":"poly_ws","payload":{"market":"0xf250e9cda122a88bffb973a0c10d67302f06c4d6d2a7a998bbd514c9b783cb9c","price_changes":[{"asset_id":"30628628256922129361568138552829834868125997804575067220632439143002067301195","price":"0.28","size":"2008","side":"BUY","hash":"b887cca296186f1dfd2eb501bb5809803ed4fb4b","best_bid":"0.33","best_ask":"0.34"},{"asset_id":"25904534922361021063199958329408275661746575318235828101794830786745156915675","price":"0.72","size":"2008","side":"SELL","hash":"4e2158f0023cebaed1edfc5bb1fc59d2e1937bd3","best_bid":"0.66","best_ask":"0.67"}],"timestamp":"1788920376881","event_type":"price_change"}}
{"ts_mono_ns":10862941926777,"ts_wall_ns":1788920377506407920,"fonte":"poly_ws","payload":{"market":"0xf250e9cda122a88bffb973a0c10d67302f06c4d6d2a7a998bbd514c9b783cb9c","price_changes":[{"asset_id":"30628628256922129361568138552829834868125997804575067220632439143002067301195","price":"0.27","size":"342.11","side":"BUY","hash":"61862363ec2c0fc445fbdcf6240563383dada2e8","best_bid":"0.33","best_ask":"0.34"},{"asset_id":"25904534922361021063199958329408275661746575318235828101794830786745156915675","price":"0.73","size":"342.11","side":"SELL","hash":"6847286594717c7171f4cea5ea5249c0ce3822ef","best_bid":"0.66","best_ask":"0.67"}],"timestamp":"1788920376882","event_type":"price_change"}}
{"ts_mono_ns":10862941944830,"ts_wall_ns":1788920377506425972,"fonte":"poly_ws","payload":{"market":"0x583e8a11679a33294b1e20a89374e4742961f151f1f05c9a0c1eb34883a7538f","price_changes":[{"asset_id":"46179897111767575621067600626085063615255126374895750367620822995125397577982","price":"0.01","size":"3630.08","side":"BUY","hash":"5f19a986148045a363f2c41300639a1451e0d087","best_bid":"0.999","best_ask":"1"},{"asset_id":"72709494218706655003179124592746636178529103451837436693660676934739929402705","price":"0.99","size":"3630.08","side":"SELL","hash":"5a080f7284f95cbaedf25458b2ce7cc075ba1386","best_bid":"0","best_ask":"0.001"}],"timestamp":"1788920376887","event_type":"price_change"}}
{"ts_mono_ns":10862941967701,"ts_wall_ns":1788920377506448844,"fonte":"poly_ws","payload":{"market":"0x583e8a11679a33294b1e20a89374e4742961f151f1f05c9a0c1eb34883a7538f","price_changes":[{"asset_id":"46179897111767575621067600626085063615255126374895750367620822995125397577982","price":"0.01","size":"3624.08","side":"BUY","hash":"865f97f5e3b246acd88cf71cbb64b30321fa4264","best_bid":"0.999","best_ask":"1"},{"asset_id":"72709494218706655003179124592746636178529103451837436693660676934739929402705","price":"0.99","size":"3624.08","side":"SELL","hash":"b9d13ccd4c12b778c840a2b40545b27bb966c533","best_bid":"0","best_ask":"0.001"}],"timestamp":"1788920376891","event_type":"price_change"}}
{"ts_mono_ns":10862941990362,"ts_wall_ns":1788920377506471547,"fonte":"poly_ws","payload":{"market":"0xf250e9cda122a88bffb973a0c10d67302f06c4d6d2a7a998bbd514c9b783cb9c","price_changes":[{"asset_id":"30628628256922129361568138552829834868125997804575067220632439143002067301195","price":"0.01","size":"1913.75","side":"BUY","hash":"bbb418066a73acfbb9de91c62a593d23c9bb349e","best_bid":"0.33","best_ask":"0.34"},{"asset_id":"25904534922361021063199958329408275661746575318235828101794830786745156915675","price":"0.99","size":"1913.75","side":"SELL","hash":"0612675ae5769a05efec9ab23f23b2bb4c843e5a","best_bid":"0.66","best_ask":"0.67"}],"timestamp":"1788920376894","event_type":"price_change"}}
{"ts_mono_ns":10862942008625,"ts_wall_ns":1788920377506489768,"fonte":"poly_ws","payload":{"market":"0x583e8a11679a33294b1e20a89374e4742961f151f1f05c9a0c1eb34883a7538f","price_changes":[{"asset_id":"46179897111767575621067600626085063615255126374895750367620822995125397577982","price":"0.83","size":"15","side":"BUY","hash":"a88739e4796c691c0305a5168ce2e048783d2aac","best_bid":"0.999","best_ask":"1"},{"asset_id":"72709494218706655003179124592746636178529103451837436693660676934739929402705","price":"0.17","size":"15","side":"SELL","hash":"a1cce4a90359dfd75c43f5c4e91904cabac37495","best_bid":"0","best_ask":"0.001"}],"timestamp":"1788920376895","event_type":"price_change"}}
{"ts_mono_ns":10862942039022,"ts_wall_ns":1788920377506520165,"fonte":"poly_ws","payload":{"market":"0xf250e9cda122a88bffb973a0c10d67302f06c4d6d2a7a998bbd514c9b783cb9c","price_changes":[{"asset_id":"25904534922361021063199958329408275661746575318235828101794830786745156915675","price":"0.62","size":"4227","side":"BUY","hash":"564a6029ca744c15893c53b53b1b068a53106674","best_bid":"0.66","best_ask":"0.67"},{"asset_id":"30628628256922129361568138552829834868125997804575067220632439143002067301195","price":"0.38","size":"4227","side":"SELL","hash":"085fa71bf8f8f311f4770e312656ebc2000e9ffc","best_bid":"0.33","best_ask":"0.34"}],"timestamp":"1788920376896","event_type":"price_change"}}
{"ts_mono_ns":10862942057836,"ts_wall_ns":1788920377506539020,"fonte":"poly_ws","payload":{"market":"0xf250e9cda122a88bffb973a0c10d67302f06c4d6d2a7a998bbd514c9b783cb9c","price_changes":[{"asset_id":"25904534922361021063199958329408275661746575318235828101794830786745156915675","price":"0.54","size":"166","side":"BUY","hash":"9394b2c57c7616a54464ae52ac93863354766c88","best_bid":"0.66","best_ask":"0.67"},{"asset_id":"30628628256922129361568138552829834868125997804575067220632439143002067301195","price":"0.46","size":"166","side":"SELL","hash":"d6d56c06a0559694b2aff07ca94e8c738c707dc0","best_bid":"0.33","best_ask":"0.34"}],"timestamp":"1788920376897","event_type":"price_change"}}
{"ts_mono_ns":10862942076142,"ts_wall_ns":1788920377506557326,"fonte":"poly_ws","payload":{"market":"0xf250e9cda122a88bffb973a0c10d67302f06c4d6d2a7a998bbd514c9b783cb9c","price_changes":[{"asset_id":"30628628256922129361568138552829834868125997804575067220632439143002067301195","price":"0.24","size":"186","side":"BUY","hash":"f348c2701b1360e2815bc99f0a7934dde5fe3f07","best_bid":"0.33","best_ask":"0.34"},{"asset_id":"25904534922361021063199958329408275661746575318235828101794830786745156915675","price":"0.76","size":"186","side":"SELL","hash":"32b7b44d90af3467bc976b6e60bc0b6e86cafbd6","best_bid":"0.66","best_ask":"0.67"}],"timestamp":"1788920376898","event_type":"price_change"}}
{"ts_mono_ns":10862942094321,"ts_wall_ns":1788920377506575463,"fonte":"poly_ws","payload":{"market":"0xf250e9cda122a88bffb973a0c10d67302f06c4d6d2a7a998bbd514c9b783cb9c","price_changes":[{"asset_id":"30628628256922129361568138552829834868125997804575067220632439143002067301195","price":"0.28","size":"1350","side":"BUY","hash":"4a9af41ff7d2d2e692d8878bb32fccbb78809237","best_bid":"0.33","best_ask":"0.34"},{"asset_id":"25904534922361021063199958329408275661746575318235828101794830786745156915675","price":"0.72","size":"1350","side":"SELL","hash":"4f6b706e584b13ef2a7bfb619158b621731f8a16","best_bid":"0.66","best_ask":"0.67"}],"timestamp":"1788920376899","event_type":"price_change"}}
{"ts_mono_ns":10862942112077,"ts_wall_ns":1788920377506593262,"fonte":"poly_ws","payload":{"market":"0xf250e9cda122a88bffb973a0c10d67302f06c4d6d2a7a998bbd514c9b783cb9c","price_changes":[{"asset_id":"25904534922361021063199958329408275661746575318235828101794830786745156915675","price":"0.62","size":"3340","side":"BUY","hash":"5f4b63208e69e32e5ba96bb1da8f81df24bfad54","best_bid":"0.66","best_ask":"0.67"},{"asset_id":"30628628256922129361568138552829834868125997804575067220632439143002067301195","price":"0.38","size":"3340","side":"SELL","hash":"84653e65c275d18081478ede5e2412bc9904fd57","best_bid":"0.33","best_ask":"0.34"}],"timestamp":"1788920376907","event_type":"price_change"}}
{"ts_mono_ns":10862942130467,"ts_wall_ns":1788920377506611610,"fonte":"poly_ws","payload":{"market":"0xf250e9cda122a88bffb973a0c10d67302f06c4d6d2a7a998bbd514c9b783cb9c","price_changes":[{"asset_id":"25904534922361021063199958329408275661746575318235828101794830786745156915675","price":"0.61","size":"1849","side":"BUY","hash":"7a008c2f6bb90524de82ac36ce3f8c94b1be7e40","best_bid":"0.66","best_ask":"0.67"},{"asset_id":"30628628256922129361568138552829834868125997804575067220632439143002067301195","price":"0.39","size":"1849","side":"SELL","hash":"132c35b94cd3b46268baf858fa111053d5ae5f62","best_bid":"0.33","best_ask":"0.34"}],"timestamp":"1788920376909","event_type":"price_change"}}
{"ts_mono_ns":10862942148054,"ts_wall_ns":1788920377506629197,"fonte":"poly_ws","payload":{"market":"0xf250e9cda122a88bffb973a0c10d67302f06c4d6d2a7a998bbd514c9b783cb9c","price_changes":[{"asset_id":"25904534922361021063199958329408275661746575318235828101794830786745156915675","price":"0.62","size":"3365","side":"BUY","hash":"bcb5559a4759fc833717c262c697d590d652b435","best_bid":"0.66","best_ask":"0.67"},{"asset_id":"30628628256922129361568138552829834868125997804575067220632439143002067301195","price":"0.38","size":"3365","side":"SELL","hash":"3f8768aac6f4c52e868812e7ffb83d03fa453f11","best_bid":"0.33","best_ask":"0.34"}],"timestamp":"1788920376909","event_type":"price_change"}}
{"ts_mono_ns":10862942165937,"ts_wall_ns":1788920377506647122,"fonte":"poly_ws","payload":{"market":"0xf250e9cda122a88bffb973a0c10d67302f06c4d6d2a7a998bbd514c9b783cb9c","price_changes":[{"asset_id":"30628628256922129361568138552829834868125997804575067220632439143002067301195","price":"0.28","size":"531","side":"BUY","hash":"66213d097f515a288918e9222744e6fb3f64e430","best_bid":"0.33","best_ask":"0.34"},{"asset_id":"25904534922361021063199958329408275661746575318235828101794830786745156915675","price":"0.72","size":"531","side":"SELL","hash":"99357b715a6cc45f66900803bb8a95df911eab8e","best_bid":"0.66","best_ask":"0.67"}],"timestamp":"1788920376910","event_type":"price_change"}}
{"ts_mono_ns":10862942183947,"ts_wall_ns":1788920377506665132,"fonte":"poly_ws","payload":{"market":"0xf250e9cda122a88bffb973a0c10d67302f06c4d6d2a7a998bbd514c9b783cb9c","price_changes":[{"asset_id":"25904534922361021063199958329408275661746575318235828101794830786745156915675","price":"0.55","size":"156","side":"BUY","hash":"f3005c046252fd738170696ecebfb33a01a9fe2e","best_bid":"0.66","best_ask":"0.67"},{"asset_id":"30628628256922129361568138552829834868125997804575067220632439143002067301195","price":"0.45","size":"156","side":"SELL","hash":"98456764032d9205d0847242edd156ddaa621158","best_bid":"0.33","best_ask":"0.34"}],"timestamp":"1788920376916","event_type":"price_change"}}
{"ts_mono_ns":10862942202042,"ts_wall_ns":1788920377506683184,"fonte":"poly_ws","payload":{"market":"0xf250e9cda122a88bffb973a0c10d67302f06c4d6d2a7a998bbd514c9b783cb9c","price_changes":[{"asset_id":"25904534922361021063199958329408275661746575318235828101794830786745156915675","price":"0.82","size":"106","side":"SELL","hash":"f3005c046252fd738170696ecebfb33a01a9fe2e","best_bid":"0.66","best_ask":"0.67"},{"asset_id":"30628628256922129361568138552829834868125997804575067220632439143002067301195","price":"0.18","size":"106","side":"BUY","hash":"98456764032d9205d0847242edd156ddaa621158","best_bid":"0.33","best_ask":"0.34"}],"timestamp":"1788920376916","event_type":"price_change"}}
{"ts_mono_ns":10862942219925,"ts_wall_ns":1788920377506701068,"fonte":"poly_ws","payload":{"market":"0x583e8a11679a33294b1e20a89374e4742961f151f1f05c9a0c1eb34883a7538f","price_changes":[{"asset_id":"46179897111767575621067600626085063615255126374895750367620822995125397577982","price":"0.83","size":"26.6","side":"BUY","hash":"fc1899715e6cc145dedb053d01e9e2baa774826e","best_bid":"0.999","best_ask":"1"},{"asset_id":"72709494218706655003179124592746636178529103451837436693660676934739929402705","price":"0.17","size":"26.6","side":"SELL","hash":"cb947e84e7f23e77d231b1f4f83f9e634ce643c6","best_bid":"0","best_ask":"0.001"}],"timestamp":"1788920376920","event_type":"price_change"}}
{"ts_mono_ns":10862942262286,"ts_wall_ns":1788920377506743429,"fonte":"poly_ws","payload":{"market":"0x73fd6c72d0bf8220003943b6e2b41292b8cd4d97c27314db06735789b59e9d09","price_changes":[{"asset_id":"113917660431940170818498786968146153783642292134565871228813850528518440127962","price":"0.37","size":"0","side":"BUY","hash":"664176b87b71e61515baedbb2117bd55cd501eca","best_bid":"0.36","best_ask":"0.38"},{"asset_id":"84363210919223921947447886444210431825911105421883946794723950657543270560538","price":"0.63","size":"0","side":"SELL","hash":"ff035083f4bb65b1acac9cad0d62d509678764d1","best_bid":"0.62","best_ask":"0.64"}],"timestamp":"1788920376921","event_type":"price_change"}}
{"ts_mono_ns":10862942279113,"ts_wall_ns":1788920377506760255,"fonte":"poly_ws","payload":{"market":"0xf250e9cda122a88bffb973a0c10d67302f06c4d6d2a7a998bbd514c9b783cb9c","price_changes":[{"asset_id":"25904534922361021063199958329408275661746575318235828101794830786745156915675","price":"0.62","size":"2845","side":"BUY","hash":"5b2da3e557203ce1516a0cf6f4f6a69dff127c9f","best_bid":"0.66","best_ask":"0.67"},{"asset_id":"30628628256922129361568138552829834868125997804575067220632439143002067301195","price":"0.38","size":"2845","side":"SELL","hash":"076734e689ba58710fd2b93496d1239134640d7d","best_bid":"0.33","best_ask":"0.34"}],"timestamp":"1788920376922","event_type":"price_change"}}
{"ts_mono_ns":10862942297376,"ts_wall_ns":1788920377506778519,"fonte":"poly_ws","payload":{"market":"0xf250e9cda122a88bffb973a0c10d67302f06c4d6d2a7a998bbd514c9b783cb9c","price_changes":[{"asset_id":"30628628256922129361568138552829834868125997804575067220632439143002067301195","price":"0.21","size":"160","side":"BUY","hash":"af75802ff9018c171a6f4a9b43fe29ff984cad5e","best_bid":"0.33","best_ask":"0.34"},{"asset_id":"25904534922361021063199958329408275661746575318235828101794830786745156915675","price":"0.79","size":"160","side":"SELL","hash":"83f7a94c1665daee7ecd2e85354e28f70374c2ce","best_bid":"0.66","best_ask":"0.67"}],"timestamp":"1788920376925","event_type":"price_change"}}
{"ts_mono_ns":10862942328703,"ts_wall_ns":1788920377506809888,"fonte":"poly_ws","payload":{"market":"0xf250e9cda122a88bffb973a0c10d67302f06c4d6d2a7a998bbd514c9b783cb9c","price_changes":[{"asset_id":"25904534922361021063199958329408275661746575318235828101794830786745156915675","price":"0.62","size":"2820","side":"BUY","hash":"f54733c6a30f6c5067359c8c9de3e810d6d22e03","best_bid":"0.66","best_ask":"0.67"},{"asset_id":"30628628256922129361568138552829834868125997804575067220632439143002067301195","price":"0.38","size":"2820","side":"SELL","hash":"0cff8cd4170ef474ef0155f4ddf6d8ed753ad3bd","best_bid":"0.33","best_ask":"0.34"}],"timestamp":"1788920376934","event_type":"price_change"}}
